<?xml version="1.0"?><robot name="pepe">
	<link name="0">
		<visual>
			<geometry>
				<cylinder length="0.35089437110595445" radius="0.5211001667870432"/>
			</geometry>
		</visual>
		<collision>
			<geometry>
				<cylinder length="0.35089437110595445" radius="0.5211001667870432"/>
			</geometry>
		</collision>
		<inertial>
			<mass value="0.2993427185894939"/>
			<inertia ixx="0.03" iyy="0.03" izz="0.03" ixy="0" ixz="0" iyx="0"/>
		</inertial>
	</link>
	<link name="11">
		<visual>
			<geometry>
				<cylinder length="1.6167235865337606" radius="0.9163464452434805"/>
			</geometry>
		</visual>
		<collision>
			<geometry>
				<cylinder length="1.6167235865337606" radius="0.9163464452434805"/>
			</geometry>
		</collision>
		<inertial>
			<mass value="4.264862617044469"/>
			<inertia ixx="0.03" iyy="0.03" izz="0.03" ixy="0" ixz="0" iyx="0"/>
		</inertial>
	</link>
	<link name="22">
		<visual>
			<geometry>
				<cylinder length="0.9702427187033971" radius="0.6138359013033038"/>
			</geometry>
		</visual>
		<collision>
			<geometry>
				<cylinder length="0.9702427187033971" radius="0.6138359013033038"/>
			</geometry>
		</collision>
		<inertial>
			<mass value="1.148510144550484"/>
			<inertia ixx="0.03" iyy="0.03" izz="0.03" ixy="0" ixz="0" iyx="0"/>
		</inertial>
	</link>
	<link name="13">
		<visual>
			<geometry>
				<cylinder length="1.6167235865337606" radius="0.9163464452434805"/>
			</geometry>
		</visual>
		<collision>
			<geometry>
				<cylinder length="1.6167235865337606" radius="0.9163464452434805"/>
			</geometry>
		</collision>
		<inertial>
			<mass value="4.264862617044469"/>
			<inertia ixx="0.03" iyy="0.03" izz="0.03" ixy="0" ixz="0" iyx="0"/>
		</inertial>
	</link>
	<link name="24">
		<visual>
			<geometry>
				<cylinder length="0.9702427187033971" radius="0.6138359013033038"/>
			</geometry>
		</visual>
		<collision>
			<geometry>
				<cylinder length="0.9702427187033971" radius="0.6138359013033038"/>
			</geometry>
		</collision>
		<inertial>
			<mass value="1.148510144550484"/>
			<inertia ixx="0.03" iyy="0.03" izz="0.03" ixy="0" ixz="0" iyx="0"/>
		</inertial>
	</link>
	<link name="15">
		<visual>
			<geometry>
				<cylinder length="1.6167235865337606" radius="0.9163464452434805"/>
			</geometry>
		</visual>
		<collision>
			<geometry>
				<cylinder length="1.6167235865337606" radius="0.9163464452434805"/>
			</geometry>
		</collision>
		<inertial>
			<mass value="4.264862617044469"/>
			<inertia ixx="0.03" iyy="0.03" izz="0.03" ixy="0" ixz="0" iyx="0"/>
		</inertial>
	</link>
	<link name="26">
		<visual>
			<geometry>
				<cylinder length="0.9702427187033971" radius="0.6138359013033038"/>
			</geometry>
		</visual>
		<collision>
			<geometry>
				<cylinder length="0.9702427187033971" radius="0.6138359013033038"/>
			</geometry>
		</collision>
		<inertial>
			<mass value="1.148510144550484"/>
			<inertia ixx="0.03" iyy="0.03" izz="0.03" ixy="0" ixz="0" iyx="0"/>
		</inertial>
	</link>
	<joint name="11_to_0" type="revolute">
		<parent link="0"/>
		<child link="11"/>
		<axis xyz="1 0 0"/>
		<limit effort="1" upper="-3.1415" lower="3.1415" velocity="1"/>
		<origin rpy="10.61683884527557 0.7206710599815701 6.282556988648868" xyz="0.30953915295501044 0.6895189303275684 0.5495245631995184"/>
	</joint>
	<joint name="22_to_11" type="revolute">
		<parent link="11"/>
		<child link="22"/>
		<axis xyz="0 1 0"/>
		<limit effort="1" upper="-3.1415" lower="3.1415" velocity="1"/>
		<origin rpy="12.253927186812717 1.437516484625504 4.5765889171154335" xyz="0.25439540509300496 0.2289664483963053 0.13768350084241276"/>
	</joint>
	<joint name="13_to_0" type="revolute">
		<parent link="0"/>
		<child link="13"/>
		<axis xyz="1 0 0"/>
		<limit effort="1" upper="-3.1415" lower="3.1415" velocity="1"/>
		<origin rpy="15.925258267913355 0.7206710599815701 6.282556988648868" xyz="0.30953915295501044 0.6895189303275684 0.5495245631995184"/>
	</joint>
	<joint name="24_to_13" type="revolute">
		<parent link="13"/>
		<child link="24"/>
		<axis xyz="0 1 0"/>
		<limit effort="1" upper="-3.1415" lower="3.1415" velocity="1"/>
		<origin rpy="12.253927186812717 1.437516484625504 4.5765889171154335" xyz="0.25439540509300496 0.2289664483963053 0.13768350084241276"/>
	</joint>
	<joint name="15_to_0" type="revolute">
		<parent link="0"/>
		<child link="15"/>
		<axis xyz="1 0 0"/>
		<limit effort="1" upper="-3.1415" lower="3.1415" velocity="1"/>
		<origin rpy="21.23367769055114 0.7206710599815701 6.282556988648868" xyz="0.30953915295501044 0.6895189303275684 0.5495245631995184"/>
	</joint>
	<joint name="26_to_15" type="revolute">
		<parent link="15"/>
		<child link="26"/>
		<axis xyz="0 1 0"/>
		<limit effort="1" upper="-3.1415" lower="3.1415" velocity="1"/>
		<origin rpy="12.253927186812717 1.437516484625504 4.5765889171154335" xyz="0.25439540509300496 0.2289664483963053 0.13768350084241276"/>
	</joint>
</robot>
