<?xml version="1.0"?><robot name="pepe">
	<link name="0">
		<visual>
			<geometry>
				<cylinder length="0.27205881734562043" radius="0.4772475267572681"/>
			</geometry>
		</visual>
		<collision>
			<geometry>
				<cylinder length="0.27205881734562043" radius="0.4772475267572681"/>
			</geometry>
		</collision>
		<inertial>
			<mass value="0.1946704583259739"/>
			<inertia ixx="0.03" iyy="0.03" izz="0.03" ixy="0" ixz="0" iyx="0"/>
		</inertial>
	</link>
	<link name="11">
		<visual>
			<geometry>
				<cylinder length="1.5622075801491697" radius="0.221245390702849"/>
			</geometry>
		</visual>
		<collision>
			<geometry>
				<cylinder length="1.5622075801491697" radius="0.221245390702849"/>
			</geometry>
		</collision>
		<inertial>
			<mass value="0.24023544052366685"/>
			<inertia ixx="0.03" iyy="0.03" izz="0.03" ixy="0" ixz="0" iyx="0"/>
		</inertial>
	</link>
	<link name="22">
		<visual>
			<geometry>
				<cylinder length="1.9198692921114313" radius="0.6291130134070801"/>
			</geometry>
		</visual>
		<collision>
			<geometry>
				<cylinder length="1.9198692921114313" radius="0.6291130134070801"/>
			</geometry>
		</collision>
		<inertial>
			<mass value="2.387145400071626"/>
			<inertia ixx="0.03" iyy="0.03" izz="0.03" ixy="0" ixz="0" iyx="0"/>
		</inertial>
	</link>
	<link name="13">
		<visual>
			<geometry>
				<cylinder length="1.5622075801491697" radius="0.221245390702849"/>
			</geometry>
		</visual>
		<collision>
			<geometry>
				<cylinder length="1.5622075801491697" radius="0.221245390702849"/>
			</geometry>
		</collision>
		<inertial>
			<mass value="0.24023544052366685"/>
			<inertia ixx="0.03" iyy="0.03" izz="0.03" ixy="0" ixz="0" iyx="0"/>
		</inertial>
	</link>
	<link name="24">
		<visual>
			<geometry>
				<cylinder length="1.9198692921114313" radius="0.6291130134070801"/>
			</geometry>
		</visual>
		<collision>
			<geometry>
				<cylinder length="1.9198692921114313" radius="0.6291130134070801"/>
			</geometry>
		</collision>
		<inertial>
			<mass value="2.387145400071626"/>
			<inertia ixx="0.03" iyy="0.03" izz="0.03" ixy="0" ixz="0" iyx="0"/>
		</inertial>
	</link>
	<link name="15">
		<visual>
			<geometry>
				<cylinder length="1.5622075801491697" radius="0.221245390702849"/>
			</geometry>
		</visual>
		<collision>
			<geometry>
				<cylinder length="1.5622075801491697" radius="0.221245390702849"/>
			</geometry>
		</collision>
		<inertial>
			<mass value="0.24023544052366685"/>
			<inertia ixx="0.03" iyy="0.03" izz="0.03" ixy="0" ixz="0" iyx="0"/>
		</inertial>
	</link>
	<link name="26">
		<visual>
			<geometry>
				<cylinder length="1.9198692921114313" radius="0.6291130134070801"/>
			</geometry>
		</visual>
		<collision>
			<geometry>
				<cylinder length="1.9198692921114313" radius="0.6291130134070801"/>
			</geometry>
		</collision>
		<inertial>
			<mass value="2.387145400071626"/>
			<inertia ixx="0.03" iyy="0.03" izz="0.03" ixy="0" ixz="0" iyx="0"/>
		</inertial>
	</link>
	<joint name="11_to_0" type="revolute">
		<parent link="0"/>
		<child link="11"/>
		<axis xyz="0 0 1"/>
		<limit effort="1" upper="-3.1415" lower="3.1415" velocity="1"/>
		<origin rpy="4.099740538878967 0.9768281932411039 5.502151616908443" xyz="0.013907691086566865 0.5897526669006181 0.0791590027893464"/>
	</joint>
	<joint name="22_to_11" type="revolute">
		<parent link="11"/>
		<child link="22"/>
		<axis xyz="1 0 0"/>
		<limit effort="1" upper="-3.1415" lower="3.1415" velocity="1"/>
		<origin rpy="0.03831934115394378 0.41064288059501824 0.9690386488452966" xyz="0.2795887692477883 0.4131671429655013 0.3857780456794021"/>
	</joint>
	<joint name="13_to_0" type="revolute">
		<parent link="0"/>
		<child link="13"/>
		<axis xyz="0 0 1"/>
		<limit effort="1" upper="-3.1415" lower="3.1415" velocity="1"/>
		<origin rpy="6.14961080831845 0.9768281932411039 5.502151616908443" xyz="0.013907691086566865 0.5897526669006181 0.0791590027893464"/>
	</joint>
	<joint name="24_to_13" type="revolute">
		<parent link="13"/>
		<child link="24"/>
		<axis xyz="1 0 0"/>
		<limit effort="1" upper="-3.1415" lower="3.1415" velocity="1"/>
		<origin rpy="0.03831934115394378 0.41064288059501824 0.9690386488452966" xyz="0.2795887692477883 0.4131671429655013 0.3857780456794021"/>
	</joint>
	<joint name="15_to_0" type="revolute">
		<parent link="0"/>
		<child link="15"/>
		<axis xyz="0 0 1"/>
		<limit effort="1" upper="-3.1415" lower="3.1415" velocity="1"/>
		<origin rpy="8.199481077757934 0.9768281932411039 5.502151616908443" xyz="0.013907691086566865 0.5897526669006181 0.0791590027893464"/>
	</joint>
	<joint name="26_to_15" type="revolute">
		<parent link="15"/>
		<child link="26"/>
		<axis xyz="1 0 0"/>
		<limit effort="1" upper="-3.1415" lower="3.1415" velocity="1"/>
		<origin rpy="0.03831934115394378 0.41064288059501824 0.9690386488452966" xyz="0.2795887692477883 0.4131671429655013 0.3857780456794021"/>
	</joint>
</robot>
