<?xml version="1.0"?><robot name="pepe">
	<link name="0">
		<visual>
			<geometry>
				<cylinder length="0.8202433794602948" radius="0.3413189181724402"/>
			</geometry>
		</visual>
		<collision>
			<geometry>
				<cylinder length="0.8202433794602948" radius="0.3413189181724402"/>
			</geometry>
		</collision>
		<inertial>
			<mass value="0.30020182443262416"/>
			<inertia ixx="0.03" iyy="0.03" izz="0.03" ixy="0" ixz="0" iyx="0"/>
		</inertial>
	</link>
	<link name="11">
		<visual>
			<geometry>
				<cylinder length="0.4582811834682781" radius="0.5147861863462972"/>
			</geometry>
		</visual>
		<collision>
			<geometry>
				<cylinder length="0.4582811834682781" radius="0.5147861863462972"/>
			</geometry>
		</collision>
		<inertial>
			<mass value="0.38153612793751907"/>
			<inertia ixx="0.03" iyy="0.03" izz="0.03" ixy="0" ixz="0" iyx="0"/>
		</inertial>
	</link>
	<link name="22">
		<visual>
			<geometry>
				<cylinder length="0.4588754422273209" radius="0.9513076101344347"/>
			</geometry>
		</visual>
		<collision>
			<geometry>
				<cylinder length="0.4588754422273209" radius="0.9513076101344347"/>
			</geometry>
		</collision>
		<inertial>
			<mass value="1.3046278063617873"/>
			<inertia ixx="0.03" iyy="0.03" izz="0.03" ixy="0" ixz="0" iyx="0"/>
		</inertial>
	</link>
	<link name="13">
		<visual>
			<geometry>
				<cylinder length="0.4582811834682781" radius="0.5147861863462972"/>
			</geometry>
		</visual>
		<collision>
			<geometry>
				<cylinder length="0.4582811834682781" radius="0.5147861863462972"/>
			</geometry>
		</collision>
		<inertial>
			<mass value="0.38153612793751907"/>
			<inertia ixx="0.03" iyy="0.03" izz="0.03" ixy="0" ixz="0" iyx="0"/>
		</inertial>
	</link>
	<link name="24">
		<visual>
			<geometry>
				<cylinder length="0.4588754422273209" radius="0.9513076101344347"/>
			</geometry>
		</visual>
		<collision>
			<geometry>
				<cylinder length="0.4588754422273209" radius="0.9513076101344347"/>
			</geometry>
		</collision>
		<inertial>
			<mass value="1.3046278063617873"/>
			<inertia ixx="0.03" iyy="0.03" izz="0.03" ixy="0" ixz="0" iyx="0"/>
		</inertial>
	</link>
	<joint name="11_to_0" type="revolute">
		<parent link="0"/>
		<child link="11"/>
		<axis xyz="1 0 0"/>
		<limit effort="1" upper="-3.1415" lower="3.1415" velocity="1"/>
		<origin rpy="10.073548019933853 4.659504663191963 2.4836470791881746" xyz="0.9995893956930538 0.5762324414224341 0.03713008470708312"/>
	</joint>
	<joint name="22_to_11" type="revolute">
		<parent link="11"/>
		<child link="22"/>
		<axis xyz="0 1 0"/>
		<limit effort="1" upper="-3.1415" lower="3.1415" velocity="1"/>
		<origin rpy="7.820595787783109 3.1197020396584545 1.1421056585581084" xyz="0.06741544734933402 0.3974508836781886 0.8113373058363587"/>
	</joint>
	<joint name="13_to_0" type="revolute">
		<parent link="0"/>
		<child link="13"/>
		<axis xyz="1 0 0"/>
		<limit effort="1" upper="-3.1415" lower="3.1415" velocity="1"/>
		<origin rpy="15.110322029900779 4.659504663191963 2.4836470791881746" xyz="0.9995893956930538 0.5762324414224341 0.03713008470708312"/>
	</joint>
	<joint name="24_to_13" type="revolute">
		<parent link="13"/>
		<child link="24"/>
		<axis xyz="0 1 0"/>
		<limit effort="1" upper="-3.1415" lower="3.1415" velocity="1"/>
		<origin rpy="7.820595787783109 3.1197020396584545 1.1421056585581084" xyz="0.06741544734933402 0.3974508836781886 0.8113373058363587"/>
	</joint>
</robot>
