<?xml version="1.0"?><robot name="pepe">
	<link name="0">
		<visual>
			<geometry>
				<cylinder length="1.051961205187508" radius="0.8476575280301925"/>
			</geometry>
		</visual>
		<collision>
			<geometry>
				<cylinder length="1.051961205187508" radius="0.8476575280301925"/>
			</geometry>
		</collision>
		<inertial>
			<mass value="2.3745998898214755"/>
			<inertia ixx="0.03" iyy="0.03" izz="0.03" ixy="0" ixz="0" iyx="0"/>
		</inertial>
	</link>
	<link name="11">
		<visual>
			<geometry>
				<cylinder length="1.051961205187508" radius="0.8476575280301925"/>
			</geometry>
		</visual>
		<collision>
			<geometry>
				<cylinder length="1.051961205187508" radius="0.8476575280301925"/>
			</geometry>
		</collision>
		<inertial>
			<mass value="2.3745998898214755"/>
			<inertia ixx="0.03" iyy="0.03" izz="0.03" ixy="0" ixz="0" iyx="0"/>
		</inertial>
	</link>
	<joint name="11_to_0" type="revolute">
		<parent link="0"/>
		<child link="11"/>
		<axis xyz="0 0 1"/>
		<limit effort="1" upper="-3.1415" lower="3.1415" velocity="1"/>
		<origin rpy="5.041387065644444 4.403987629821016 4.274801344455181" xyz="0.11866751810199896 0.12529649260884057 0.45253033493619765"/>
	</joint>
</robot>
