<?xml version="1.0"?><robot name="pepe">
	<link name="0">
		<visual>
			<geometry>
				<cylinder length="1.2490119846959788" radius="0.17071792976729408"/>
			</geometry>
		</visual>
		<collision>
			<geometry>
				<cylinder length="1.2490119846959788" radius="0.17071792976729408"/>
			</geometry>
		</collision>
		<inertial>
			<mass value="0.11436015872527709"/>
			<inertia ixx="0.03" iyy="0.03" izz="0.03" ixy="0" ixz="0" iyx="0"/>
		</inertial>
	</link>
	<link name="11">
		<visual>
			<geometry>
				<cylinder length="0.5683753194119094" radius="0.5275679522764753"/>
			</geometry>
		</visual>
		<collision>
			<geometry>
				<cylinder length="0.5683753194119094" radius="0.5275679522764753"/>
			</geometry>
		</collision>
		<inertial>
			<mass value="0.4969834148786758"/>
			<inertia ixx="0.03" iyy="0.03" izz="0.03" ixy="0" ixz="0" iyx="0"/>
		</inertial>
	</link>
	<link name="12">
		<visual>
			<geometry>
				<cylinder length="0.5683753194119094" radius="0.5275679522764753"/>
			</geometry>
		</visual>
		<collision>
			<geometry>
				<cylinder length="0.5683753194119094" radius="0.5275679522764753"/>
			</geometry>
		</collision>
		<inertial>
			<mass value="0.4969834148786758"/>
			<inertia ixx="0.03" iyy="0.03" izz="0.03" ixy="0" ixz="0" iyx="0"/>
		</inertial>
	</link>
	<link name="13">
		<visual>
			<geometry>
				<cylinder length="0.5683753194119094" radius="0.5275679522764753"/>
			</geometry>
		</visual>
		<collision>
			<geometry>
				<cylinder length="0.5683753194119094" radius="0.5275679522764753"/>
			</geometry>
		</collision>
		<inertial>
			<mass value="0.4969834148786758"/>
			<inertia ixx="0.03" iyy="0.03" izz="0.03" ixy="0" ixz="0" iyx="0"/>
		</inertial>
	</link>
	<joint name="11_to_0" type="revolute">
		<parent link="0"/>
		<child link="11"/>
		<axis xyz="0 1 0"/>
		<limit effort="1" upper="-3.1415" lower="3.1415" velocity="1"/>
		<origin rpy="6.80662796085286 2.843485811118293 5.074191252773964" xyz="0.19428614908922373 0.6224771454401942 0.3715902029451882"/>
	</joint>
	<joint name="12_to_0" type="revolute">
		<parent link="0"/>
		<child link="12"/>
		<axis xyz="0 1 0"/>
		<limit effort="1" upper="-3.1415" lower="3.1415" velocity="1"/>
		<origin rpy="10.20994194127929 2.843485811118293 5.074191252773964" xyz="0.19428614908922373 0.6224771454401942 0.3715902029451882"/>
	</joint>
	<joint name="13_to_0" type="revolute">
		<parent link="0"/>
		<child link="13"/>
		<axis xyz="0 1 0"/>
		<limit effort="1" upper="-3.1415" lower="3.1415" velocity="1"/>
		<origin rpy="13.61325592170572 2.843485811118293 5.074191252773964" xyz="0.19428614908922373 0.6224771454401942 0.3715902029451882"/>
	</joint>
</robot>
